<?xml version="1.0"?>
<!-- PAROL6 6自由度机械臂 MuJoCo模型 -->
<mujoco model="parol6">
    <compiler angle="radian" meshdir="meshes" autolimits="true" eulerseq="xyz"/>
    
    <visual>
        <headlight diffuse="0.6 0.6 0.6" ambient="0.3 0.3 0.3" specular="0 0 0"/>
        <rgba haze="0.15 0.25 0.35 1"/>
        <global offwidth="2560" offheight="1440"/>
        <quality shadowsize="4096"/>
        <map stiffness="700" shadowscale="0.5" fogstart="10" fogend="15" zfar="40"/>
    </visual>
    
    <option timestep="0.002" iterations="50" solver="Newton" gravity="0 0 -9.81" cone="elliptic"/>
    
    <asset>
        <texture name="grid" type="2d" builtin="checker" width="512" height="512"
                 rgb1="0.1 0.2 0.3" rgb2="0.2 0.3 0.4"/>
        <material name="grid" texture="grid" texrepeat="1 1" texuniform="true" reflectance="0.2"/>
        
        <mesh name="base_link" file="base_link.STL" scale="0.001 0.001 0.001"/>
        <mesh name="l1" file="L1.STL" scale="0.001 0.001 0.001"/>
        <mesh name="l2" file="L2.STL" scale="0.001 0.001 0.001"/>
        <mesh name="l3" file="L3.STL" scale="0.001 0.001 0.001"/>
        <mesh name="l4" file="L4.STL" scale="0.001 0.001 0.001"/>
        <mesh name="l5" file="L5.STL" scale="0.001 0.001 0.001"/>
        <mesh name="l6" file="L6.STL" scale="0.001 0.001 0.001"/>
    </asset>
    
    <default>
        <joint damping="0.5" armature="0.01"/>
        <geom contype="1" conaffinity="1" condim="3" friction="0.8 0.1 0.1"/>
        <motor ctrlrange="-1 1" ctrllimited="true"/>
        <position ctrlrange="-3.14 3.14" kp="10"/>
    </default>
    
    <worldbody>
        <geom name="floor" type="plane" size="2 2 0.1" material="grid"
              condim="3" contype="1" conaffinity="1"/>
        
        <light pos="0 0 3" dir="0 0 -1" directional="false" diffuse="0.8 0.8 0.8"/>
        <light pos="2 2 3" dir="-1 -1 -1" directional="false" diffuse="0.4 0.4 0.4"/>
        
        <body name="base_link" pos="0 0 0">
            <inertial pos="-0.0275 -0.0014 0.0312" mass="0.8127" diaginertia="0.001479 0.001107 0.001066"/>
            <geom type="mesh" mesh="base_link" rgba="0.75 0.75 0.75 1"/>
            
            <body name="L1" pos="0 0 0" quat="1 0 0 0">
                <inertial pos="0.0052 0.0290 0.0993" mass="0.6448" diaginertia="0.001295 0.001094 0.000570"/>
                <joint name="L1" type="hinge" axis="0 0 1" range="-1.7 1.7" damping="1.0"/>
                <geom type="mesh" mesh="l1" rgba="0.75 0.75 0.75 1"/>
                
                <body name="L2" pos="0.0234 0 0.1105" quat="0.7071 -0.7071 0 0">
                    <inertial pos="-0.0094 -0.0784 0.0369" mass="0.5123" diaginertia="0.001322 0.001234 0.000205"/>
                    <joint name="L2" type="hinge" axis="0 0 1" range="-0.98 1.0" damping="1.0"/>
                    <geom type="mesh" mesh="l2" rgba="0.75 0.75 0.75 1"/>
                    
                    <body name="L3" pos="0 -0.18 0" quat="0 0.7071 -0.7071 0">
                        <inertial pos="0.0156 -0.0191 -0.0015" mass="0.5510" diaginertia="0.000816 0.000578 0.000567"/>
                        <joint name="L3" type="hinge" axis="0 0 -1" range="-2.0 1.3" damping="1.0"/>
                        <geom type="mesh" mesh="l3" rgba="0.75 0.75 0.75 1"/>
                        
                        <body name="L4" pos="0.0435 0 0" quat="0 0 0.7071 0.7071">
                            <inertial pos="0.0009 -0.0090 -0.0925" mass="0.3935" diaginertia="0.000372 0.000332 0.000251"/>
                            <joint name="L4" type="hinge" axis="0 0 -1" range="-2.0 2.0" damping="1.0"/>
                            <geom type="mesh" mesh="l4" rgba="0.75 0.75 0.75 1"/>
                            
                            <body name="L5" pos="0 0 -0.17635" quat="0.7071 -0.7071 0 0">
                                <inertial pos="0.0000 -0.0062 -0.0010" mass="0.1852" diaginertia="0.000111 0.000109 0.000084"/>
                                <joint name="L5" type="hinge" axis="0 0 -1" range="-2.1 2.1" damping="1.0"/>
                                <geom type="mesh" mesh="l5" rgba="0.75 0.75 0.75 1"/>
                                
                                <body name="L6" pos="0 0 0" quat="0.7071 0.7071 0 0">
                                    <inertial pos="0.0063 -0.0005 -0.0554" mass="0.0703" diaginertia="0.000023 0.000018 0.000014"/>
                                    <joint name="L6" type="hinge" axis="0 0 -1" limited="false" damping="0.3"/>
                                    <geom type="mesh" mesh="l6" rgba="0.75 0.75 0.75 1"/>
                                    <site name="end_effector" pos="0 0 -0.08" size="0.01"/>
                                </body>
                            </body>
                        </body>
                    </body>
                </body>
            </body>
        </body>
        
        <camera name="fixed" pos="1.5 1.5 1.5" xyaxes="-1 1 0 -0.5 -0.5 1" mode="fixed"/>
        <camera name="top" pos="0 0 2" xyaxes="1 0 0 0 1 0" mode="fixed"/>
        <camera name="side" pos="2 0 0.5" xyaxes="0 1 0 0 0 1" mode="fixed"/>
    </worldbody>
    
    <actuator>
        <position name="L1_motor" joint="L1" kp="100" ctrlrange="-1.7 1.7"/>
        <position name="L2_motor" joint="L2" kp="100" ctrlrange="-0.98 1.0"/>
        <position name="L3_motor" joint="L3" kp="100" ctrlrange="-2.0 1.3"/>
        <position name="L4_motor" joint="L4" kp="80" ctrlrange="-2.0 2.0"/>
        <position name="L5_motor" joint="L5" kp="80" ctrlrange="-2.1 2.1"/>
        <position name="L6_motor" joint="L6" kp="50" ctrlrange="-3.14 3.14"/>
    </actuator>
    
    <sensor>
        <jointpos name="L1_pos" joint="L1"/>
        <jointpos name="L2_pos" joint="L2"/>
        <jointpos name="L3_pos" joint="L3"/>
        <jointpos name="L4_pos" joint="L4"/>
        <jointpos name="L5_pos" joint="L5"/>
        <jointpos name="L6_pos" joint="L6"/>
        <jointvel name="L1_vel" joint="L1"/>
        <jointvel name="L2_vel" joint="L2"/>
        <jointvel name="L3_vel" joint="L3"/>
        <jointvel name="L4_vel" joint="L4"/>
        <jointvel name="L5_vel" joint="L5"/>
        <jointvel name="L6_vel" joint="L6"/>
    </sensor>
</mujoco>